<?xml version="1.0"?>
<robot name="myfirst">

  <material name="black">
    <color rgba="0 0 0 1"/>
  </material>

  <material name="red">
    <color rgba="1 0 0 1"/>
  </material>

  <material name="white">
    <color rgba="1 1 1 1"/>
  </material>




  <link name="base_link">
     <visual>
        <geometry>
          <cylinder length="0.05" radius="0.6"/>
        </geometry>
        <material name="red"/>
     </visual>
     <collision>
        <geometry>
          <cylinder length="0.05" radius="0.6"/>
        </geometry>
     </collision>
     <inertial>
       <mass value="10"/>
       <inertia ixx="1.0" ixy="0.0" ixz="0.0" iyy="1.0" iyz="0.0" izz="1.0"/>
     </inertial>
  </link>

  <link name="right_leg1">
    <visual>
      <geometry>
         <cylinder length="0.7" radius="0.03"/>
      </geometry>
      <origin rpy="0 1.5787 0" xyz="0 0.2 0.3"/>
      <material name="black"/>
    </visual>
    <collision>
        <geometry>
         <cylinder length="0.7" radius="0.03"/>
        </geometry>
        <origin rpy="0 1.5787 0" xyz="0 0.2 0.3"/>
    </collision>
    <inertial>
       <mass value="1"/>
       <inertia ixx="1.0" ixy="0.0" ixz="0.0" iyy="1.0" iyz="0.0" izz="1.0"/>
    </inertial>
  </link>

  <joint name="base_to_rigth_leg1" type="fixed">
     <parent link="base_link"/>
     <child link="right_leg1"/>
     <origin rpy="0 2 0" xyz="0.3 0.18 0.45"/>
  </joint>

  <link name="right_leg1_1">
    <visual>
      <geometry>
         <cylinder length="0.9" radius="0.03"/>
      </geometry>
      <origin rpy="0 1.5787 0" xyz="0 0.2 0.15"/>
      <material name="black"/>
    </visual>
     <collision>
        <geometry>
         <cylinder length="0.9" radius="0.03"/>
        </geometry>
        <origin rpy="0 1.5787 0" xyz="0 0.2 0.15"/>
     </collision>
     <inertial>
       <mass value="1"/>
       <inertia ixx="1.0" ixy="0.0" ixz="0.0" iyy="1.0" iyz="0.0" izz="1.0"/>
     </inertial>
  </link>

  <joint name="base_to_rigth_leg1_1" type="revolute">
     <parent link="right_leg1"/>
     <child link="right_leg1_1"/>
     <origin rpy="0 2 0" xyz="-0.3 0 0.75 "/>
     <axis xyz="0 1 0"/>
     <limit effort="10" lower="-0.1" upper="0.1" velocity="3"/>
  </joint>

  <gazebo reference="right_leg1_1">
     <material>Gazebo/Grey</material>
     <static>true</static>
  </gazebo>


  <link name="right_leg_whell_1_1">
    <visual>
      <geometry>
         <cylinder length="0.1" radius="0.03"/>
      </geometry>
      <origin  xyz="0 0 0"/>
      <material name="black"/>
    </visual>
     <collision>
        <geometry>
         <cylinder length="0.1" radius="0.03"/>
        </geometry>
        <origin  xyz="0 0 0"/>
     </collision>
     <inertial>
       <mass value="1"/>
      <inertia ixx="1.0" ixy="0.0" ixz="0.0" iyy="1.0" iyz="0.0" izz="1.0"/>
     </inertial>
  </link>

  <joint name="base_to_rigth_legwhell_1_1" type="continuous">
     <parent link="right_leg1_1"/>
     <child link="right_leg_whell_1_1"/>
     <axis xyz="0 0 1" />
     <origin rpy="0 0.72 0 " xyz="-0.425 0.2 0.17 "/>
  </joint>


  <gazebo reference="right_leg_whell_1_1">
     <mu1 value="200.0"/>
     <mu2 value="100.0"/>
     <kp value="10000000.0"/>
     <kd value="1.0"/>
     <material>Gazebo/Grey</material>
  </gazebo>
  <gazebo reference="right_leg_whell_2_1">
     <mu1 value="200.0"/>
     <mu2 value="100.0"/>
     <kp value="10000000.0"/>
     <kd value="1.0"/>
     <material>Gazebo/Grey</material>
  </gazebo>

  <gazebo reference="right_leg_whell_3_1">
     <mu1 value="200.0"/>
     <mu2 value="100.0"/>
     <kp value="10000000.0"/>
     <kd value="1.0"/>
     <material>Gazebo/Grey</material>
  </gazebo>
  <gazebo reference="left_leg_whell_1_1">
     <mu1 value="200.0"/>
     <mu2 value="100.0"/>
     <kp value="10000000.0"/>
     <kd value="1.0"/>
     <material>Gazebo/Grey</material>
  </gazebo>

  <gazebo reference="left_leg_whell_2_1">
     <mu1 value="200.0"/>
     <mu2 value="100.0"/>
     <kp value="10000000.0"/>
     <kd value="1.0"/>
     <material>Gazebo/Grey</material>
  </gazebo>

  <gazebo reference="left_leg_whell_3_1">
     <mu1 value="200.0"/>
     <mu2 value="100.0"/>
     <kp value="10000000.0"/>
     <kd value="1.0"/>
     <material>Gazebo/Grey</material>
  </gazebo>




  



  <link name="right_leg2">
    <visual>
      <geometry>
         <cylinder length="0.7" radius="0.03"/>
      </geometry>
      <origin rpy="0 1.5787 0" xyz="0 -0.2 0.4"/>
      <material name="black"/>
    </visual>
     <collision>
        <geometry>
         <cylinder length="0.7" radius="0.03"/>
        </geometry>
        <origin rpy="0 1.5787 0" xyz="0 -0.2 0.4"/>
     </collision>
     <inertial>
       <mass value="1"/>
      <inertia ixx="1.0" ixy="0.0" ixz="0.0" iyy="1.0" iyz="0.0" izz="1.0"/>
     </inertial>

  </link>

  <joint name="base_to_rigth_leg2" type="fixed">
     <parent link="base_link"/>
     <child link="right_leg2"/>
     <origin rpy="0 2 0" xyz="0.3 0.18 0.45"/>
  </joint>

  <link name="right_leg2_1">
    <visual>
      <geometry>
         <cylinder length="0.9" radius="0.03"/>
      </geometry>
      <origin rpy="0 1.5787 0" xyz="0 0.2 0.15"/>
      <material name="black"/>
    </visual>
     <collision>
        <geometry>
         <cylinder length="0.9" radius="0.03"/>
        </geometry>
        <origin rpy="0 1.5787 0" xyz="0 0.2 0.15"/>
     </collision>
     <inertial>
       <mass value="1"/>
      <inertia ixx="1.0" ixy="0.0" ixz="0.0" iyy="1.0" iyz="0.0" izz="1.0"/>
     </inertial>
  </link>

  <joint name="base_to_rigth_leg2_1" type="revolute">
     <parent link="right_leg2"/>
     <child link="right_leg2_1"/>
     <origin rpy="0 2 0" xyz="-0.3 -0.4 0.85 "/>
     <axis xyz="0 1 0"/>
     <limit effort="10" lower="-0.1" upper="0.1" velocity="3"/>
  </joint>

  <link name="right_leg_whell_2_1">
    <visual>
      <geometry>
         <cylinder length="0.1" radius="0.03"/>
      </geometry>
      <origin  xyz="0 0 0"/>
      <material name="gray"/>
    </visual>
     <collision>
        <geometry>
         <cylinder length="0.1" radius="0.03"/>
        </geometry>
        <origin xyz="0 0 0"/>
     </collision>
     <inertial>
       <mass value="1"/>
      <inertia ixx="1.0" ixy="0.0" ixz="0.0" iyy="1.0" iyz="0.0" izz="1.0"/>
     </inertial>
  </link>

  <joint name="base_to_rigth_legwhell_2_1" type="continuous">
     <parent link="right_leg2_1"/>
     <child link="right_leg_whell_2_1"/>
     <axis xyz="0 0 1" />
     <origin rpy="0 0.72 0 " xyz="-0.425 0.2 0.17 "/>
  </joint>

  <link name="right_leg3">
    <visual>
      <geometry>
         <cylinder length="0.7" radius="0.03"/>
      </geometry>
      <origin rpy="0 1.5787 0" xyz="0 -0.45 0.3"/>
      <material name="black"/>
    </visual>
     <collision>
        <geometry>
         <cylinder length="0.7" radius="0.03"/>
        </geometry>
        <origin rpy="0 1.5787 0" xyz="0 -0.45 0.3"/>
     </collision>
     <inertial>
       <mass value="1"/>
      <inertia ixx="1.0" ixy="0.0" ixz="0.0" iyy="1.0" iyz="0.0" izz="1.0"/>
     </inertial>
  </link>

  <joint name="base_to_rigth_leg3" type="fixed">
     <parent link="base_link"/>
     <child link="right_leg3"/>
     <origin rpy="0 2 0" xyz="0.3 0.1 0.45"/>
  </joint>

  <link name="right_leg3_1">
    <visual>
      <geometry>
         <cylinder length="0.9" radius="0.03"/>
      </geometry>
      <origin rpy="0 1.5787 0" xyz="0 0.2 0.15"/>
      <material name="black"/>
    </visual>
     <collision>
        <geometry>
         <cylinder length="0.9" radius="0.03"/>
        </geometry>
        <origin rpy="0 1.5787 0" xyz="0 0.2 0.15"/>
     </collision>
     <inertial>
       <mass value="1"/>
      <inertia ixx="1.0" ixy="0.0" ixz="0.0" iyy="1.0" iyz="0.0" izz="1.0"/>
     </inertial>
  </link>

  <joint name="base_to_rigth_leg3_1" type="revolute">
     <parent link="right_leg3"/>
     <child link="right_leg3_1"/>
     <origin rpy="0 2 0" xyz="-0.3 -0.65 0.75 "/>
     <axis xyz="0 1 0"/>
     <limit effort="10" lower="-0.1" upper="0.1" velocity="3"/>
  </joint>

  <link name="right_leg_whell_3_1">
    <visual>
      <geometry>
         <cylinder length="0.1" radius="0.03"/>
      </geometry>
      <origin  xyz="0 0 0"/>
      <material name="gray"/>
    </visual>
     <collision>
        <geometry>
         <cylinder length="0.1" radius="0.03"/>
        </geometry>
        <origin xyz="0 0 0"/>
     </collision>
     <inertial>
       <mass value="1"/>
      <inertia ixx="1.0" ixy="0.0" ixz="0.0" iyy="1.0" iyz="0.0" izz="1.0"/>
     </inertial>
  </link>

  <joint name="base_to_rigth_legwhell_3_1" type="continuous">
     <parent link="right_leg3_1"/>
     <child link="right_leg_whell_3_1"/>
     <axis xyz="0 0 1" />
     <origin rpy="0 0.72 0 " xyz="-0.425 0.2 0.17 "/>
  </joint>

  <link name="left_leg1">
    <visual>
      <geometry>
         <cylinder length="0.7" radius="0.03"/>
      </geometry>
      <origin rpy="0 1.5787 0" xyz="0 0.2 0.3"/>
      <material name="black"/>
    </visual>
     <collision>
        <geometry>
         <cylinder length="0.7" radius="0.03"/>
        </geometry>
        <origin rpy="0 1.5787 0" xyz="0 0.2 0.3"/>
     </collision>
     <inertial>
       <mass value="1"/>
      <inertia ixx="1.0" ixy="0.0" ixz="0.0" iyy="1.0" iyz="0.0" izz="1.0"/>
     </inertial>
  </link>

  <joint name="base_to_left_leg1" type="fixed">
     <parent link="base_link"/>
     <child link="left_leg1"/>
     <origin rpy="0 -2 0" xyz="-0.3 0.18 0.45"/>
  </joint>
<link name="left_leg1_1">
    <visual>
      <geometry>
         <cylinder length="0.9" radius="0.03"/>
      </geometry>
      <origin rpy="0 1.5787 0" xyz="0 0.2 0.15"/>
      <material name="black"/>
    </visual>
     <collision>
        <geometry>
         <cylinder length="0.9" radius="0.03"/>
        </geometry>
        <origin rpy="0 1.5787 0" xyz="0 0.2 0.15"/>
     </collision>
     <inertial>
       <mass value="1"/>
      <inertia ixx="1.0" ixy="0.0" ixz="0.0" iyy="1.0" iyz="0.0" izz="1.0"/>
     </inertial>
  </link>

  <joint name="base_to_left_leg1_1" type="revolute">
     <parent link="left_leg1"/>
     <child link="left_leg1_1"/>
     <origin rpy="0 -2 0" xyz="0.3 0 0.75 "/>
     <axis xyz="0 1 0"/>
     <limit effort="10" lower="-0.1" upper="0.1" velocity="3"/>
  </joint>


  <link name="left_leg_whell_1_1">
    <visual>
      <geometry>
         <cylinder length="0.1" radius="0.03"/>
      </geometry>
      <origin  xyz="0 0 0"/>
      <material name="black"/>
    </visual>
     <collision>
        <geometry>
         <cylinder length="0.1" radius="0.03"/>
        </geometry>
        <origin xyz="0 0 0"/>
     </collision>
     <inertial>
       <mass value="1"/>
      <inertia ixx="1.0" ixy="0.0" ixz="0.0" iyy="1.0" iyz="0.0" izz="1.0"/>
     </inertial>
  </link>

  <joint name="base_to_left_legwhell_1_1" type="continuous">
     <parent link="left_leg1_1"/>
     <child link="left_leg_whell_1_1"/>
     <axis xyz="0 0 1" />
     <origin rpy="0 -0.72 0 " xyz="0.435 0.2 0.15 "/>
  </joint>

 <link name="left_leg2">
    <visual>
      <geometry>
         <cylinder length="0.7" radius="0.03"/>
      </geometry>
      <origin rpy="0 1.5787 0" xyz="0 -0.2 0.4"/>
      <material name="black"/>
    </visual>
     <collision>
        <geometry>
         <cylinder length="0.7" radius="0.03"/>
        </geometry>
        <origin rpy="0 1.5787 0" xyz="0 -0.2 0.4"/>
     </collision>
     <inertial>
       <mass value="1"/>
      <inertia ixx="1.0" ixy="0.0" ixz="0.0" iyy="1.0" iyz="0.0" izz="1.0"/>
     </inertial>
  </link>

  <joint name="base_to_left_leg2" type="fixed">
     <parent link="base_link"/>
     <child link="left_leg2"/>
     <origin rpy="0 -2 0" xyz="-0.3 0.18 0.45"/>
  </joint>

  <link name="left_leg2_1">
    <visual>
      <geometry>
         <cylinder length="0.9" radius="0.03"/>
      </geometry>
      <origin rpy="0 1.5787 0" xyz="0 0.2 0.15"/>
      <material name="black"/>
    </visual>
     <collision>
        <geometry>
         <cylinder length="0.9" radius="0.03"/>
        </geometry>
        <origin rpy="0 1.5787 0" xyz="0 0.2 0.15"/>
     </collision>
     <inertial>
       <mass value="1"/>
      <inertia ixx="1.0" ixy="0.0" ixz="0.0" iyy="1.0" iyz="0.0" izz="1.0"/>
     </inertial>
  </link>

  <joint name="base_to_left_leg2_1" type="revolute">
     <parent link="left_leg2"/>
     <child link="left_leg2_1"/>
     <origin rpy="0 -2 0" xyz="0.3 -0.4 0.85 "/>
     <axis xyz="0 1 0"/>
     <limit effort="10" lower="-0.1" upper="0.1" velocity="3"/>
  </joint>


  <link name="left_leg_whell_2_1">
    <visual>
      <geometry>
         <cylinder length="0.1" radius="0.03"/>
      </geometry>
      <origin  xyz="0 0 0"/>
      <material name="black"/>
    </visual>
     <collision>
        <geometry>
         <cylinder length="0.1" radius="0.03"/>
        </geometry>
        <origin xyz="0 0 0"/>
     </collision>
     <inertial>
       <mass value="1"/>
      <inertia ixx="1.0" ixy="0.0" ixz="0.0" iyy="1.0" iyz="0.0" izz="1.0"/>
     </inertial>
  </link>

  <joint name="base_to_left_legwhell_2_1" type="continuous">
     <parent link="left_leg2_1"/>
     <child link="left_leg_whell_2_1"/>
     <axis xyz="0 0 1" />
     <origin rpy="0 -0.72 0 " xyz="0.425 0.2 0.165 "/>
  </joint>


  <link name="left_leg3">
    <visual>
      <geometry>
         <cylinder length="0.7" radius="0.03"/>
      </geometry>
      <origin rpy="0 1.5787 0" xyz="0 -0.45 0.3"/>
      <material name="black"/>
    </visual>
     <collision>
        <geometry>
         <cylinder length="0.7" radius="0.03"/>
        </geometry>
        <origin rpy="0 1.5787 0" xyz="0 -0.45 0.3"/>
     </collision>
     <inertial>
       <mass value="1"/>
      <inertia ixx="1.0" ixy="0.0" ixz="0.0" iyy="1.0" iyz="0.0" izz="1.0"/>
     </inertial>
  </link>

  <joint name="base_to_left_leg3" type="fixed">
     <parent link="base_link"/>
     <child link="left_leg3"/>
     <origin rpy="0 -2 0" xyz="-0.3 0.1 0.45"/>
  </joint>

  <link name="left_leg3_1">
    <visual>
      <geometry>
         <cylinder length="0.9" radius="0.03"/>
      </geometry>
      <origin rpy="0 1.5787 0" xyz="0 0.2 0.15"/>
      <material name="black"/>
    </visual>
     <collision>
        <geometry>
         <cylinder length="0.9" radius="0.03"/>
        </geometry>
        <origin rpy="0 1.5787 0" xyz="0 0.2 0.15"/>
     </collision>
     <inertial>
       <mass value="1"/>
      <inertia ixx="1.0" ixy="0.0" ixz="0.0" iyy="1.0" iyz="0.0" izz="1.0"/>
     </inertial>
  </link>

  <joint name="base_to_left_leg3_1" type="revolute">
     <parent link="left_leg3"/>
     <child link="left_leg3_1"/>
     <origin rpy="0 -2 0" xyz="0.3 -0.65 0.75 "/>
     <axis xyz="0 1 0"/>
     <limit effort="10" lower="-0.1" upper="0.1" velocity="3"/>
  </joint>

  <link name="left_leg_whell_3_1">
    <visual>
      <geometry>
         <cylinder length="0.1" radius="0.03"/>
      </geometry>
      <origin  xyz="0 0 0"/>
      <material name="black"/>
    </visual>
     <collision>
        <geometry>
         <cylinder length="0.1" radius="0.03"/>
        </geometry>
        <origin xyz="0 0 0"/>
     </collision>
     <inertial>
       <mass value="1"/>
      <inertia ixx="1.0" ixy="0.0" ixz="0.0" iyy="1.0" iyz="0.0" izz="1.0"/>
     </inertial>
  </link>

  <joint name="base_to_left_legwhell_3_1" type="continuous">
     <parent link="left_leg3_1"/>
     <child link="left_leg_whell_3_1"/>
     <axis xyz="0 0 1" />
     <origin rpy="0 -0.72 0 " xyz="0.425 0.2 0.165 "/>
  </joint>




  <link name="head">
    <visual>
      <geometry>
         <sphere radius="0.15"/>
      </geometry>
      <material name="black"/>
    </visual>
     <collision>
        <geometry>
          <sphere radius="0.15"/>
        </geometry>
     </collision>
     <inertial>
       <mass value="0.5"/>
      <inertia ixx="1.0" ixy="0.0" ixz="0.0" iyy="1.0" iyz="0.0" izz="1.0"/>
     </inertial>
  </link>

  <joint name="head_swivel" type="continuous">
     <parent link="base_link"/>
     <child link="head"/>
     <axis xyz="0 0 1"/>
     <origin xyz="0 0.5 0.15 "/>
     <limit effort="30" velocity="1.0"/>
  </joint>


  <transmission name="head_swivel_trans">
     <type>transmission_interface/SimpleTransmission</type>
     <actuator name="$head_swivel_motor">
       <mechanicalReduction>1</mechanicalReduction>
     </actuator>
     <joint name="head_swivel">
       <hardwareInterface>hardware_interface/PositionJointInterface</hardwareInterface>
     </joint>
  </transmission>





  <link name="box">
    <visual>
      <geometry>
        <box size="0.08 0.08 0.08"/>
      </geometry>
      <material name="white"/>
    </visual>
    <collision>
      <geometry>
        <box size="0.08 0.08 0.08"/>
      </geometry>
    </collision>
     <inertial>
       <mass value="0.55"/>
      <inertia ixx="1.0" ixy="0.0" ixz="0.0" iyy="1.0" iyz="0.0" izz="1.0"/>
     </inertial>
  </link>

  <joint name="boxto" type="fixed">
    <parent link="head"/>
    <child link="box"/>
    <origin xyz="0 0.15 0"/>
  </joint>

<transmission name="right_leg_whell_1_1_trans">
     <type>transmission_interface/SimpleTransmission</type>
     <actuator name="$right_leg_whell_1_1_motor">
       <mechanicalReduction>1</mechanicalReduction>
     </actuator>
     <joint name="right_leg_whell_1_1">
       <hardwareInterface>VelocityJointInterface</hardwareInterface>
     </joint>
  </transmission>
  <transmission name="right_leg_whell_2_1_trans">
     <type>transmission_interface/SimpleTransmission</type>
     <actuator name="$right_leg_whell_2_1_motor">
       <mechanicalReduction>1</mechanicalReduction>
     </actuator>
     <joint name="right_leg_whell_2_1">
       <hardwareInterface>VelocityJointInterface</hardwareInterface>
     </joint>
  </transmission>
  <transmission name="right_leg_whell_3_1_trans">
     <type>transmission_interface/SimpleTransmission</type>
     <actuator name="$right_leg_whell_3_1_motor">
       <mechanicalReduction>1</mechanicalReduction>
     </actuator>
     <joint name="right_leg_whell_3_1">
       <hardwareInterface>VelocityJointInterface</hardwareInterface>
     </joint>
  </transmission>
  <transmission name="left_leg_whell_1_1_trans">
     <type>transmission_interface/SimpleTransmission</type>
     <actuator name="$left_leg_whell_1_1_motor">
       <mechanicalReduction>1</mechanicalReduction>
     </actuator>
     <joint name="left_leg_whell_1_1">
       <hardwareInterface>VelocityJointInterface</hardwareInterface>
     </joint>
  </transmission>
  <transmission name="left_leg_whell_2_1_trans">
     <type>transmission_interface/SimpleTransmission</type>
     <actuator name="$left_leg_whell_2_1_motor">
       <mechanicalReduction>1</mechanicalReduction>
     </actuator>
     <joint name="left_leg_whell_2_1">
       <hardwareInterface>VelocityJointInterface</hardwareInterface>
     </joint>
  </transmission>
  <transmission name="left_leg_whell_3_1_trans">
     <type>transmission_interface/SimpleTransmission</type>
     <actuator name="$left_leg_whell_3_1_motor">
       <mechanicalReduction>1</mechanicalReduction>
     </actuator>
     <joint name="left_leg_whell_3_1">
       <hardwareInterface>VelocityJointInterface</hardwareInterface>
     </joint>
  </transmission>







  <gazebo>
    <plugin name="gazebo_ros_control" filename="libgazebo_ros_control.so">
      <robotNamespace>/</robotNamespace>
      <legacyModeNS>true</legacyModeNS>
    </plugin>
  </gazebo>





</robot>

